#VRML_SIM R2022a utf8
WorldInfo {
  info [
    "Bicycle Simulation"
  ]
  title "Bicycle"
  CFM 0.0003
  ERP 0.6
  basicTimeStep 1
  lineScale 1
  contactProperties [
    ContactProperties {
      coulombFriction [
        8
      ]
      bounce 0.001
      softCFM 0.0003
    }
  ]
}
Viewpoint {
  orientation 0.02783315224865285 0.1352114087452986 -0.9904257622765146 0.870201410277698
  position -0.1887935419006868 0.37396570562475284 0.1237468702722362
  near 0.1
  follow "Bicycle"
  followSmoothness 0.1
}
TexturedBackground {
}
TexturedBackgroundLight {
}
CircleArena {
  radius 200
  floorAppearance Parquetry {
    type "light strip"
  }
  floorTileSize 2 2
  wallThickness 0.1
  wallHeight 1
  wallAppearance OldPlywood {
  }
}
DEF sueprvisor Robot {
  translation 0 0 0.02
  controller "Bicycle_supervisor"
  supervisor TRUE
}
DEF MOTORCYCLE Bicycle {
  bicycle_shape FALSE
  CenterMass 0.2
  CenterHeight 0.04
  a 0.07
  b 0.157
  c 0.008
  lambda 1.05
  FrontWheelR 0.03
  RearWheelR 0.027
  WheelmassF 0.01
  WheelmassR 0.01
  FrontforkM 0.01
  tireRadius 0.003
  Xff 0.125
  Zff 0.08
  Addon [
    HingeJoint {
      jointParameters HingeJointParameters {
        anchor 0.055 0 0.1
      }
      device [
        PositionSensor {
          name "pendulum_position"
        }
        RotationalMotor {
          name "balance_servo"
          controlPID 100 0 10
          minPosition -1.5708
          maxPosition 1.5708
        }
      ]
      endPoint Solid {
        translation 0.055 0 0.15
        rotation 1 0 0 0
        children [
          Transform {
            translation 0 0 -0.03
            children [
              Shape {
                appearance PBRAppearance {
                }
                geometry Box {
                  size 0.0015 0.0015 0.05
                }
              }
            ]
          }
          Shape {
            appearance PBRAppearance {
            }
            geometry Sphere {
              radius 0.01
            }
          }
        ]
        boundingObject Shape {
          geometry Sphere {
            radius 0.01
          }
        }
        physics Physics {
          mass 0.0025
        }
      }
    }
    Shape {
      appearance RoughPolymer {
        baseColor 0.1 0.1 0.1
      }
      geometry Mesh {
        url [
          "meshes/microbike_body.obj"
        ]
      }
    }
  ]
  Addon_Front [
    Transform {
      translation -0.125 0 -0.08
      scale 0.0254 0.0254 0.0254
      children [
        Shape {
          appearance RoughPolymer {
            baseColor 0.1 0.1 0.1
          }
          geometry Mesh {
            url [
              "meshes/microbike_fork.obj"
            ]
          }
        }
      ]
    }
  ]
  controller "StepResponseTest"
}
