#VRML_SIM R2022a utf8
WorldInfo {
  info [
    "Bicycle Simulation"
  ]
  title "Bicycle"
  CFM 0.0003
  ERP 0.6
  basicTimeStep 1
  lineScale 1
  contactProperties [
    ContactProperties {
      coulombFriction [
        8
      ]
      bounce 0.001
      softCFM 0.0003
    }
  ]
}
Viewpoint {
  orientation -0.14595489801427353 0.35840777481277714 -0.9220851558827942 0.15403896860945115
  position -0.6707203475619123 0.01675156371584286 0.10158297278349439
  near 0.1
  follow "Bicycle"
  followSmoothness 0.1
}
TexturedBackground {
}
TexturedBackgroundLight {
}
CircleArena {
  radius 200
  floorAppearance Parquetry {
    type "light strip"
  }
  floorTileSize 2 2
  wallThickness 0.1
  wallHeight 1
  wallAppearance OldPlywood {
  }
}
DEF sueprvisor Robot {
  translation 0 0 0.02
  controller "Bicycle_supervisor"
  supervisor TRUE
}
DEF MOTORCYCLE Bicycle {
  bicycle_shape FALSE
  Rotation 1 0 0 0.01
  CenterMass 0.2
  CenterHeight 0.04
  a 0.07
  b 0.157
  c 0.008
  lambda 1.05
  FrontWheelR 0.03
  RearWheelR 0.027
  WheelmassF 0.01
  WheelmassR 0.01
  FrontforkM 0.01
  tireRadius 0.003
  Xff 0.125
  Zff 0.08
  Addon [
    HingeJoint {
      jointParameters HingeJointParameters {
        position -0.01
        anchor 0.055 0 0.1
      }
      device [
        PositionSensor {
          name "pendulum_position"
        }
        RotationalMotor {
          name "balance_servo"
          controlPID 0.03306250000000001 0 0.002875000000000001
          minPosition -1.5708
          maxPosition 1.5708
        }
      ]
      endPoint Solid {
        translation 0.055 0.0004999916667083332 0.14999750002083326
        rotation -1 0 0 0.01000000000000101
        children [
          Shape {
            appearance PBRAppearance {
            }
            geometry Sphere {
              radius 0.01
            }
          }
        ]
        boundingObject Shape {
          geometry Sphere {
            radius 0.01
          }
        }
        physics Physics {
          mass 0.025
        }
      }
    }
    Shape {
      appearance RoughPolymer {
        baseColor 0.1 0.1 0.1
      }
      geometry Mesh {
        url [
          "meshes/microbike_body.obj"
        ]
      }
    }
  ]
  Addon_Front [
    Transform {
      translation -0.125 0 -0.08
      scale 0.0254 0.0254 0.0254
      children [
        Shape {
          appearance RoughPolymer {
            baseColor 0.1 0.1 0.1
          }
          geometry Mesh {
            url [
              "meshes/microbike_fork.obj"
            ]
          }
        }
      ]
    }
  ]
  controller "PID_Steer_and_Balancer"
}
